Workbook
Name An: IF(CLEVER=TRUE,MIN(80,choix_an+29),choix_an+29)
Name An_calcul: [0]!choix_an_calcul+29
Name Cep_biomasse: 1
Name Cep_fossiles: 1
Name Cep_géothermie: 1
Name ConvC02C: (12+16*2)/12
Name ConvCO2C: (12+16*2)/12
Name ConvGWhVersTep: 86
Name ConvVPMLenMtep: 0.806
Name DiesterTep: 0.000807
Name EssenceTep: 0.000786
Name F_choix: IF(#REF!="S",IF(sobriété=TRUE,#REF!,#REF!),IF(#REF!="E",IF(efficacité=TRUE,#REF!,#REF!),IF(#REF!="EN",IF(ENR=TRUE,#REF!,#REF!),#REF!)))
Name G: 1000000000
Name GazoleTep: 0.000845
Name GNVTep: 0.000811
Name k: 1000
Name KérozèneTep: 0.000828
Name M: 1000000
Name Mtep_TWh: 11.628
Name MtepenTWh: 0.086
Name Nh_an: 8760
Name P: PI()/180
Name PCI_PCS_biomasse: IF(#REF!=1,1,PCS_biomasse)
Name PCI_PCS_charbon: IF(#REF!=1,1,PCS_charbon)
Name PCI_PCS_dechets: IF(PCS_PCI=1,1,PCS_dechets)
Name PCI_PCS_gaz: IF(#REF!=1,1,PCS_GN)
Name PCI_PCS_H2: IF(#REF!=1,1,PCS_H2)
Name PCI_PCS_petrole: IF(#REF!=1,1,PCS_petrole)
Name PCS_biomasse: 1.09
Name PCS_biomasse_solide: 1.09
Name PCS_charbon: 1.052
Name PCS_dechets: 1.064
Name PCS_fioul: 1.075
Name PCS_gaz: 1.111
Name PCS_GN: 1.111
Name PCS_GPL: 1.087
Name PCS_H2: 141860/119930
Name PCS_PCI: IF(#REF!=TRUE,2,#REF!)
Name PCS_PCI_biomasse: IF(PCS_PCI=1,PCS_biomasse,1)
Name PCS_PCI_charbon: IF(PCS_PCI=1,PCS_charbon,1)
Name PCS_PCI_dechets: IF(PCS_PCI=1,PCS_dechets,1)
Name PCS_PCI_gaz: IF(PCS_PCI=1,PCS_GN,1)
Name PCS_PCI_GPL: IF(PCS_PCI=1,PCS_GPL,1)
Name PCS_PCI_H2: IF(PCS_PCI=1,PCS_H2,1)
Name PCS_PCI_petrole: IF(PCS_PCI=1,PCS_petrole,1)
Name PCS_petrole: 1.075
Name pi: PI()
Name SHAB_SHON: 1
Name T: 10^12
Name TepTWh: 11.63*10^-6
Name TWh_GJ: 3600000
Name year_simulated: Constants!$B$2

Sheet Légende - Sources

Sheet ACCUEIL
A1: Descriptif des pages
A4: Nom | B4: Descriptif | C4: Indexation
A5: Data_EOLES | B5: feuille avec toutes les données de nW utiles à EOLES
A6: traitement_nW_EOLES | B6: Calculs intermédiaires pour données exploitables avec EOLES
A7: create_demand_param | B7: Constantes du problème pour la pipeline de construction de la demande horaire
A8: Constants | B8: constantes du problème non repertoriées ailleurs | C8: n
A9: Costs | B9: coûts des différentes technologies | C9: tech
A10: fuel_prices | B10: coût des ressources fossiles (natural_gas et coal) | C10: tech
A11: tech_parameters | B11: paramètres techniques des différentes technologies | C11: tech
A12: reserve | B12: paramètres techniques des marchés de réserve | C12: reserve
A13: exist_cap | B13: capacités de production existantes (en puissance) | C13: areas, tech
A14: exist_en_cap | B14: capacités de production existantes (en énergie) | C14: areas, tech
A15: min_cap | B15: capacités de production existantes (en puissance) | C15: areas, tech
A16: min_en_cap | B16: capacités de production existantes (en énergie) | C16: areas, tech
A17: max_cap | B17: capacités de production existantes (en puissance) | C17: areas, tech
A18: max_en_cap | B18: capacités de production existantes (en énergie) | C18: areas, tech
A19: links | B19: capacités d'interconnexions entre les pays | C19: areas, areas
... A21: demand_EU | B21: demandes globales par pays pour chaque vecteur (élec et gaz) | C21: areas, vectors

Sheet Data_EOLES
A1: Catégorie EOLES | B1: Usage EOLES | C1: Code EOLES | D1: Secteur | E1: Profil | F1: Libellé | G1: Unité | H1: Code SnW27 | I1: Module SnW27 | J1: 2019 | K1: =J1+1 -> 2020 | L1: =K1+1 -> 2021 | M1: =L1+1 -> 2022 | N1: =M1+1 -> 2023 | O1: =N1+1 -> 2024 | P1: =O1+1 -> 2025 | Q1: =P1+1 -> 2026 | R1: =Q1+1 -> 2027 | ... BI1: =BH1+1 -> 2070 | BJ1: Libellé dans BDD indicateurs | BK1: Pour somme demande élec
A2: Courbe de charge elec | B2: donnée nécessitant un traitement dans traitement_nW_EOLES | C2: demand_elec_res_heat | D2: Résidentiel | E2: Thermosensible chaud | F2: Conso d'élec pour chauffage résidentiel (effet joule + électricité des PAC) | G2: TWh/an | H2: elccfreschf | I2: bâtiment_démographie_v2.6 | J2: 48.47084 | K2: 44.72675 | L2: 45.52188 | M2: 41.8848 | N2: 38.35691 | O2: 37.0631 | P2: 36.91469 | Q2: 36.77802 | R2: 36.66374 | S2: 36.57943 | T2: 36.5349 | U2: 36.54035 | V2: 36.57321 | W2: 36.66549 | X2: 36.80986 | Y2: 36.99546 | Z2: 37.20951 | AA2: 37.42921 | AB2: 37.6157 | AC2: 37.72222 | AD2: 37.7096 | AE2: 37.55723 | AF2: 37.26582 | AG2: 36.85582 | AH2: 36.3602 | AI2: 35.81675 | AJ2: 34.84306 | AK2: 33.72558 | AL2: 32.65873 | AM2: 31.64907 | AN2: 30.6911 | AO2: 29.77571 | AP2: 29.26579 | AQ2: 28.81425 | AR2: 28.42498 | AS2: 28.09388 | AT2: 27.99908 | AU2: 27.91781 | AV2: 27.82532 | AW2: 27.75478 | AX2: 27.68513 | AY2: 27.61632 | AZ2: 27.54848 | BA2: 27.48176 | BB2: 27.41638 | BC2: 27.35258 | BD2: 27.29059 | BE2: 27.23068 | BF2: 27.17308 | BG2: 27.11812 | BH2: 27.06633 | BI2: 27.01697 | BJ2: Consommation finale d'électricité pour le chauffage des locaux | BK2: TRUE
A3: Courbe de charge elec | B3: donnée nécessitant un traitement dans traitement_nW_EOLES | C3: demand_elec_res_cool | D3: Résidentiel | E3: Thermosensible froid | F3: Conso d'élec pour clim résidentiel | G3: TWh/an | H3: elccfrescli | I3: bâtiment_démographie_v2.6 | J3: 2.63834 | K3: 2.81314 | L3: 2.7415 | M3: 2.66986 | N3: 2.59822 | O3: 2.52658 | P3: 2.45494 | Q3: 2.38329 | R3: 2.31165 | S3: 2.24001 | T3: 2.16837 | U3: 2.09673 | V3: 2.15077 | W3: 2.20482 | X3: 2.25886 | Y3: 2.3129 | Z3: 2.36694 | AA3: 2.42099 | AB3: 2.47503 | AC3: 2.52907 | AD3: 2.58311 | AE3: 2.63716 | AF3: 2.70747 | AG3: 2.77778 | AH3: 2.84809 | AI3: 2.9184 | AJ3: 2.98872 | AK3: 3.05903 | AL3: 3.12934 | AM3: 3.19965 | AN3: 3.26996 | AO3: =6+3.34028 -> 9.34028 | AP3: 3.34028 | AQ3: 3.34028 | AR3: 3.34028 | AS3: 3.34028 | AT3: 3.34028 | AU3: 3.34028 | AV3: 3.34028 | AW3: 3.34028 | AX3: 3.34028 | AY3: 3.34028 | AZ3: 3.34028 | BA3: 3.34028 | BB3: 3.34028 | BC3: 3.34028 | BD3: 3.34028 | BE3: 3.34028 | BF3: 3.34028 | BG3: 3.34028 | BH3: 3.34028 | BI3: 3.34028 | BJ3: #N/A | BK3: TRUE
A4: Courbe de charge elec | B4: donnée non utilisée mais vérif de cohérence sur cet onglet | C4: demand_elec | D4: Résidentiel | E4: Flexible | F4: Eau chaude sanitaire résidentiel | G4: TWh/an | H4: elccfresecs | I4: bâtiment_démographie_v2.6 | J4: 23.54842 | K4: 24.15811 | L4: 24.00329 | M4: 23.87498 | N4: 23.74596 | O4: 23.61225 | P4: 23.43499 | Q4: 23.25899 | R4: 23.06652 | S4: 22.85036 | T4: 22.60113 | U4: 22.30644 | V4: 21.95166 | W4: 21.51912 | X4: 20.98907 | Y4: 20.34663 | Z4: 19.58952 | AA4: 18.72964 | AB4: 17.78878 | AC4: 16.79572 | AD4: 15.78491 | AE4: 14.79282 | AF4: 13.85359 | AG4: 12.99359 | AH4: 12.23018 | AI4: 11.57133 | AJ4: 11.01671 | AK4: 10.55947 | AL4: 10.18833 | AM4: 9.88982 | AN4: 9.64988 | AO4: 9.4551 | AP4: 9.29372 | AQ4: 9.15603 | AR4: 9.0344 | AS4: 8.92321 | AT4: 8.81862 | AU4: 8.71816 | AV4: 8.62029 | AW4: 8.52415 | AX4: 8.42928 | AY4: 8.33555 | AZ4: 8.24293 | BA4: 8.15137 | BB4: 8.06095 | BC4: 7.97174 | BD4: 7.88376 | BE4: 7.79706 | BF4: 7.71161 | BG4: 7.62741 | BH4: 7.54443 | BI4: 7.46245 | BJ4: Consommation finale d'électricité pour l'eau chaude sanitaire | BK4: TRUE
A5: Courbe de charge elec | B5: donnée non utilisée mais vérif de cohérence sur cet onglet | C5: demand_elec | D5: Résidentiel | E5: Base | F5: Cuisson résidentiel | G5: TWh/an | H5: elccfrescui | I5: bâtiment_démographie_v2.6 | J5: 11.43404 | K5: 11.49283 | L5: 11.49989 | M5: 11.54846 | N5: 11.54021 | O5: 11.54129 | P5: 11.54815 | Q5: 11.54849 | R5: 11.54848 | S5: 11.54954 | T5: 11.55082 | U5: 11.55067 | V5: 11.56449 | W5: 11.57161 | X5: 11.57451 | Y5: 11.57351 | Z5: 11.56722 | AA5: 11.55051 | AB5: 11.53024 | AC5: 11.50576 | AD5: 11.47782 | AE5: 11.44568 | AF5: 11.41174 | AG5: 11.37752 | AH5: 11.33698 | AI5: 11.29355 | AJ5: 11.25397 | AK5: 11.19814 | AL5: 11.13958 | AM5: 11.07856 | AN5: 11.01599 | AO5: 10.95011 | AP5: 10.86319 | AQ5: 10.77684 | AR5: 10.69197 | AS5: 10.60695 | AT5: 10.52402 | AU5: 10.4556 | AV5: 10.38962 | AW5: 10.33228 | AX5: 10.2715 | AY5: 10.21387 | AZ5: 10.20199 | BA5: 10.19091 | BB5: 10.18092 | BC5: 10.1723 | BD5: 10.16536 | BE5: 10.1604 | BF5: 10.15773 | BG5: 10.1577 | BH5: 10.16065 | BI5: 10.16587 | BJ5: Consommation électrique finale pour la cuisson domestique | BK5: TRUE
A6: Courbe de charge elec | B6: donnée non utilisée mais vérif de cohérence sur cet onglet | C6: demand_elec | D6: Résidentiel | E6: Base | F6: Eclairage et équipements domestiques résidentiel | G6: TWh/an | H6: elecfresels | I6: bâtiment_démographie_v2.6 | J6: 61.46746 | K6: 60.49832 | L6: 59.46206 | M6: 58.22864 | N6: 57.27204 | O6: 56.35774 | P6: 55.69386 | Q6: 54.9437 | R6: 54.32433 | S6: 53.57981 | T6: 52.90193 | U6: 52.14314 | V6: 51.39607 | W6: 50.61336 | X6: 49.73607 | Y6: 48.89056 | Z6: 48.03674 | AA6: 47.2159 | AB6: 46.39659 | AC6: 45.59354 | AD6: 44.7931 | AE6: 43.98136 | AF6: 43.28281 | AG6: 42.5638 | AH6: 41.858 | AI6: 41.17545 | AJ6: 40.47455 | AK6: 39.85535 | AL6: 39.25918 | AM6: 38.65958 | AN6: 38.0836 | AO6: 37.51643 | AP6: 37.11088 | AQ6: 36.73396 | AR6: 36.3857 | AS6: 36.04544 | AT6: 35.73098 | AU6: 35.42412 | AV6: 35.12693 | AW6: 34.84289 | AX6: 34.57394 | AY6: 34.31166 | AZ6: 34.437 | BA6: 34.56435 | BB6: 34.69471 | BC6: 34.82915 | BD6: 34.96878 | BE6: 34.95351 | BF6: 34.94589 | BG6: 34.94708 | BH6: 34.95829 | BI6: 34.97717 | BJ6: Électricité spécifique | BK6: TRUE
A7: Courbe de charge elec | B7: donnée non utilisée mais vérif de cohérence sur cet onglet | C7: demand_elec | D7: Résidentiel | E7: Base | F7: Autre élec spécifique résidentiel (ventilation, portes auto, ascenseurs etc.) | G7: TWh/an | H7: elccfresbmg | I7: bâtiment_démographie_v2.6 | J7: 12.31708 | K7: 12.08928 | L7: 11.90191 | M7: 11.71528 | N7: 11.48913 | O7: 11.26854 | P7: 11.05675 | Q7: 10.83909 | R7: 10.62517 | S7: 10.41785 | T7: 10.22151 | U7: 10.0415 | V7: 9.94382 | W7: 9.8859 | X7: 9.87377 | Y7: 9.90752 | Z7: 9.9802 | AA7: 10.0807 | AB7: 10.20109 | AC7: 10.33705 | AD7: 10.48493 | AE7: 10.64278 | AF7: 10.80621 | AG7: 10.97841 | AH7: 11.15873 | AI7: 11.34493 | AJ7: 11.53984 | AK7: 11.74112 | AL7: 11.75829 | AM7: 11.78032 | AN7: 11.80378 | AO7: 11.8218 | AP7: 11.87645 | AQ7: 11.92889 | AR7: 11.97892 | AS7: 12.02639 | AT7: 12.0712 | AU7: 12.18622 | AV7: 12.28619 | AW7: 12.35609 | AX7: 12.42094 | AY7: 12.48109 | AZ7: 12.46781 | BA7: 12.45538 | BB7: 12.44415 | BC7: 12.43447 | BD7: 12.42673 | BE7: 12.42131 | BF7: 12.4186 | BG7: 12.41902 | BH7: 12.423 | BI7: 12.42971 | BJ7: #N/A | BK7: TRUE
A8: Courbe de charge elec | B8: donnée nécessitant un traitement dans traitement_nW_EOLES | C8: demand_elec_res | D8: Résidentiel | F8: TOTAL | G8: TWh/an | H8: elccfres | I8: bâtiment_démographie_v2.6 | J8: 159.87619 | K8: 155.77842 | L8: 155.13052 | M8: 149.92202 | N8: 145.00248 | O8: 142.3695 | P8: 141.10338 | Q8: 139.75159 | R8: 138.53989 | S8: 137.21699 | T8: 135.97866 | U8: 134.67883 | V8: 133.58002 | W8: 132.46029 | X8: 131.24214 | Y8: 130.02658 | Z8: 128.75012 | AA8: 127.42694 | AB8: 126.00742 | AC8: 124.48337 | AD8: 122.83348 | AE8: 121.05702 | AF8: 119.32763 | AG8: 117.54692 | AH8: 115.79219 | AI8: 114.12042 | AJ8: 112.11685 | AK8: 110.13868 | AL8: 108.13344 | AM8: 106.25701 | AN8: 104.51431 | AO8: 102.85942 | AP8: 101.75032 | AQ8: 100.75025 | AR8: 99.85624 | AS8: 99.03614 | AT8: 98.48418 | AU8: 98.04218 | AV8: 97.58863 | AW8: 97.15046 | AX8: 96.72106 | AY8: 96.29877 | AZ8: 96.23847 | BA8: 96.18404 | BB8: 96.13739 | BC8: 96.10052 | BD8: 96.0755 | BE8: 95.90322 | BF8: 95.7472 | BG8: 95.60961 | BH8: 95.49297 | BI8: 95.39246
A9: Courbe de charge elec | B9: donnée non utilisée mais vérif de cohérence sur cet onglet | C9: demand_elec | D9: Résidentiel | F9: DELTA TOTAL vs. somme | G9: TWh/an | J9: =J8-SUM(J2:J7) -> 1e-05 | K9: =K8-SUM(K2:K7) -> -1e-05 | L9: =L8-SUM(L2:L7) -> -1e-05 | M9: =M8-SUM(M2:M7) -> 0 | N9: =N8-SUM(N2:N7) -> 1e-05 | O9: =O8-SUM(O2:O7) -> 0 | P9: =P8-SUM(P2:P7) -> 0 | Q9: =Q8-SUM(Q2:Q7) -> 1e-05 | ... BI9: =BI8-SUM(BI2:BI7) -> 1e-05
A11: Courbe de charge elec | B11: donnée nécessitant un traitement dans traitement_nW_EOLES | C11: demand_elec_ter_heat | D11: Tertiaire | E11: Thermosensible chaud | F11: Conso d'élec pour chauffage tertiaire (effet joule + électricité des PAC) | G11: TWh/an | H11: elccfterchf | I11: bâtiment_démographie_v2.6 | J11: 23.74654 | K11: 23.49369 | L11: 23.57614 | M11: 22.11833 | N11: 20.9132 | O11: 20.8733 | P11: 20.83607 | Q11: 20.80356 | R11: 20.77722 | S11: 20.75703 | T11: 20.73991 | U11: 20.7173 | V11: 20.66716 | W11: 20.57812 | X11: 20.43439 | Y11: 20.23017 | Z11: 19.97013 | AA11: 19.6635 | AB11: 19.31066 | AC11: 18.86838 | AD11: 18.39653 | AE11: 17.89397 | AF11: 17.35949 | AG11: 16.79237 | AH11: 16.19292 | AI11: 15.56331 | AJ11: 14.90783 | AK11: 14.23456 | AL11: 13.55445 | AM11: 12.88005 | AN11: 12.22418 | AO11: 11.59836 | AP11: 11.01158 | AQ11: 10.46973 | AR11: 9.97562 | AS11: 9.52937 | AT11: 9.12905 | AU11: 8.7713 | AV11: 8.45187 | AW11: 8.16603 | AX11: 7.90898 | AY11: 7.67608 | AZ11: 7.46309 | BA11: 7.26625 | BB11: 7.08237 | BC11: 6.90883 | BD11: 6.74264 | BE11: 6.57972 | BF11: 6.42208 | BG11: 6.27472 | BH11: 6.15613 | BI11: 6.0352 | BJ11: #N/A | BK11: TRUE
A12: Courbe de charge elec | B12: donnée nécessitant un traitement dans traitement_nW_EOLES | C12: demand_elec_ter_cool | D12: Tertiaire | E12: Thermosensible froid | F12: Conso d'élec pour clim tertiaire | G12: TWh/an | H12: elccftercli | I12: bâtiment_démographie_v2.6 | J12: 13.5157 | K12: 13.4038 | L12: 15.46657 | M12: 15.52641 | N12: 15.58476 | O12: 15.63895 | P12: 15.68799 | Q12: 15.732 | R12: 15.77105 | S12: 15.80526 | T12: 15.8348 | U12: 15.85965 | V12: 15.87989 | W12: 15.89563 | X12: 15.90682 | Y12: 15.91348 | Z12: 15.9156 | AA12: 15.91325 | AB12: 15.90645 | AC12: 15.89525 | AD12: 15.87972 | AE12: 15.85992 | AF12: 15.836 | AG12: 15.80805 | AH12: 15.77617 | AI12: 15.74047 | AJ12: 15.70113 | AK12: 15.65821 | AL12: 15.6117 | AM12: 15.5617 | AN12: 15.5083 | AO12: 15.45151 | AP12: 15.58463 | AQ12: 15.71498 | AR12: 15.84244 | AS12: 15.96692 | AT12: 16.08841 | AU12: 16.20691 | AV12: 16.32247 | AW12: 16.4351 | AX12: 16.54484 | AY12: 16.65179 | AZ12: 16.75605 | BA12: 16.85758 | BB12: 16.95647 | BC12: 17.05278 | BD12: 17.14651 | BE12: 17.23769 | BF12: 17.32629 | BG12: 17.41227 | BH12: 17.49561 | BI12: 17.57547 | BJ12: #N/A | BK12: TRUE
A13: Courbe de charge elec | B13: donnée non utilisée mais vérif de cohérence sur cet onglet | C13: demand_elec | D13: Tertiaire | E13: Flexible | F13: Eau chaude sanitaire tertiaire | G13: TWh/an | H13: elccfterecs | I13: bâtiment_démographie_v2.6 | J13: 9.26042 | K13: 8.851 | L13: 8.79514 | M13: 8.80224 | N13: 8.74277 | O13: 8.68158 | P13: 8.6169 | Q13: 8.54716 | R13: 8.46988 | S13: 8.38149 | T13: 8.27729 | U13: 8.15142 | V13: 7.99754 | W13: 7.80983 | X13: 7.58432 | Y13: 7.32049 | Z13: 7.0223 | AA13: 6.69836 | AB13: 6.36071 | AC13: 6.02283 | AD13: 5.69739 | AE13: 5.39455 | AF13: 5.12109 | AG13: 4.88035 | AH13: 4.67279 | AI13: 4.49675 | AJ13: 4.34925 | AK13: 4.22649 | AL13: 4.12442 | AM13: 4.03909 | AN13: 3.96683 | AO13: 3.90441 | AP13: 3.8491 | AQ13: 3.79877 | AR13: 3.75174 | AS13: 3.70681 | AT13: 3.66318 | AU13: 3.62032 | AV13: 3.57792 | AW13: 3.53581 | AX13: 3.49389 | AY13: 3.45216 | AZ13: 3.41061 | BA13: 3.36925 | BB13: 3.32809 | BC13: 3.28716 | BD13: 3.24648 | BE13: 3.20605 | BF13: 3.16588 | BG13: 3.12598 | BH13: 3.08634 | BI13: 3.04682 | BJ13: #N/A | BK13: TRUE
A14: Courbe de charge elec | B14: donnée non utilisée mais vérif de cohérence sur cet onglet | C14: demand_elec | D14: Tertiaire | E14: Base | F14: Cuisson tertiaire | G14: TWh/an | H14: elccftercui | I14: bâtiment_démographie_v2.6 | J14: 5.3257 | K14: 5.4472 | L14: 5.56632 | M14: 5.69366 | N14: 5.81351 | O14: 5.92378 | P14: 6.00527 | Q14: 6.08499 | R14: 6.14619 | S14: 6.19721 | T14: 6.24646 | U14: 6.2772 | V14: 6.24363 | W14: 6.20016 | X14: 6.14704 | Y14: 6.09246 | Z14: 6.02859 | AA14: 5.96347 | AB14: 5.8971 | AC14: 5.82201 | AD14: 5.74594 | AE14: 5.66892 | AF14: 5.58388 | AG14: 5.49826 | AH14: 5.41903 | AI14: 5.33228 | AJ14: 5.24517 | AK14: 5.15771 | AL14: 5.06987 | AM14: 4.98172 | AN14: 4.89329 | AO14: 4.80456 | AP14: 4.80129 | AQ14: 4.79763 | AR14: 4.79356 | AS14: 4.78906 | AT14: 4.78417 | AU14: 4.77893 | AV14: 4.77342 | AW14: 4.76767 | AX14: 4.76175 | AY14: 4.75575 | AZ14: 4.74976 | BA14: 4.74378 | BB14: 4.7379 | BC14: 4.73216 | BD14: 4.72661 | BE14: 4.72128 | BF14: 4.71618 | BG14: 4.71131 | BH14: 4.70668 | BI14: 4.70217 | BJ14: #N/A | BK14: TRUE
A15: Courbe de charge elec | B15: donnée non utilisée mais vérif de cohérence sur cet onglet | C15: demand_elec | D15: Tertiaire | E15: Pro | F15: Final electricity consumption for lighting in the tertiary sector | G15: TWh/an | H15: elccfterlgt | I15: bâtiment_démographie_v2.6 | J15: 14.55733 | K15: 14.05568 | L15: 13.06644 | M15: 12.24169 | N15: 11.44946 | O15: 10.74544 | P15: 10.11489 | Q15: 9.54668 | R15: 9.03183 | S15: 8.56302 | T15: 8.13427 | U15: 7.74052 | V15: 7.33843 | W15: 6.97062 | X15: 6.63278 | Y15: 6.32129 | Z15: 6.03309 | AA15: 5.7656 | AB15: 5.51661 | AC15: 5.2842 | AD15: 5.06674 | AE15: 4.8628 | AF15: 4.82147 | AG15: 4.77966 | AH15: 4.73741 | AI15: 4.69887 | AJ15: 4.6815 | AK15: 4.66343 | AL15: 4.64463 | AM15: 4.62513 | AN15: 4.60494 | AO15: 4.5684 | AP15: 4.55434 | AQ15: 4.53066 | AR15: 4.50631 | AS15: 4.48129 | AT15: 4.45562 | AU15: 4.42932 | AV15: 4.40244 | AW15: 4.37499 | AX15: 4.34702 | AY15: 4.31857 | AZ15: 4.3064 | BA15: 4.29371 | BB15: 4.28051 | BC15: 4.26684 | BD15: 4.25272 | BE15: 4.23814 | BF15: 4.22312 | BG15: 4.20767 | BH15: 4.19177 | BI15: 4.17526 | BJ15: #N/A | BK15: TRUE
A16: Courbe de charge elec | B16: donnée non utilisée mais vérif de cohérence sur cet onglet | C16: demand_elec | D16: Tertiaire | E16: Pro | F16: Final electricity consumption for IT equipment (desktop, laptop, screen) in the tertiary sector | G16: TWh/an | H16: elccfterite | I16: bâtiment_démographie_v2.6 | J16: 8.58105 | K16: 8.33488 | L16: 8.0804 | M16: 7.8811 | N16: 7.65539 | O16: 7.43265 | P16: 7.21237 | Q16: 7.03654 | R16: 6.86511 | S16: 6.69805 | T16: 6.53532 | U16: 6.37684 | V16: 6.22252 | W16: 6.07231 | X16: 5.9261 | Y16: 5.78378 | Z16: 5.64527 | AA16: 5.5614 | AB16: 5.47778 | AC16: 5.3943 | AD16: 5.31092 | AE16: 5.16443 | AF16: 5.06145 | AG16: 4.96024 | AH16: 4.86076 | AI16: 4.78047 | AJ16: 4.70576 | AK16: 4.6312 | AL16: 4.5568 | AM16: 4.48259 | AN16: 4.46583 | AO16: 4.44043 | AP16: 4.42565 | AQ16: 4.40614 | AR16: 4.38605 | AS16: 4.36538 | AT16: 4.34416 | AU16: 4.32754 | AV16: 4.31443 | AW16: 4.3007 | AX16: 4.28639 | AY16: 4.27154 | AZ16: 4.2595 | BA16: 4.24694 | BB16: 4.2339 | BC16: 4.22038 | BD16: 4.2064 | BE16: 4.19199 | BF16: 4.17713 | BG16: 4.16184 | BH16: 4.14612 | BI16: 4.12979 | BJ16: #N/A | BK16: TRUE
A17: Courbe de charge elec | B17: donnée non utilisée mais vérif de cohérence sur cet onglet | C17: demand_elec | D17: Tertiaire | E17: Pro | F17: Final electricity consumption for other office equipment (refrigeration, washing, excl. servers) | G17: TWh/an | H17: elccfterooe | I17: bâtiment_démographie_v2.6 | J17: 3.91339 | K17: 4.00354 | L17: 4.04435 | M17: 4.10336 | N17: 4.16093 | O17: 4.21641 | P17: 4.26951 | Q17: 4.27275 | R17: 4.27143 | S17: 4.26555 | T17: 4.25512 | U17: 4.22469 | V17: 4.19036 | W17: 4.13743 | X17: 4.06693 | Y17: 3.97996 | Z17: 3.87762 | AA17: 3.77433 | AB17: 3.77809 | AC17: 3.78119 | AD17: 3.78362 | AE17: 3.7854 | AF17: 3.78654 | AG17: 3.78704 | AH17: 3.78692 | AI17: 3.78619 | AJ17: 3.78488 | AK17: 3.78297 | AL17: 3.78047 | AM17: 3.77738 | AN17: 3.77371 | AO17: 3.76945 | AP17: 3.76459 | AQ17: 3.75913 | AR17: 3.75307 | AS17: 3.7464 | AT17: 3.73913 | AU17: 3.73129 | AV17: 3.72288 | AW17: 3.71394 | AX17: 3.70448 | AY17: 3.69453 | AZ17: 3.68412 | BA17: 3.67326 | BB17: 3.66197 | BC17: 3.65028 | BD17: 3.63819 | BE17: 3.62572 | BF17: 3.61288 | BG17: 3.59965 | BH17: 3.58605 | BI17: 3.57193 | BJ17: #N/A | BK17: TRUE
A18: Courbe de charge elec | B18: donnée non utilisée mais vérif de cohérence sur cet onglet | C18: demand_elec | D18: Tertiaire | E18: ? | F18: Final electricity consumption for public lighting | G18: TWh/an | H18: elccfterplg | I18: bâtiment_démographie_v2.6 | J18: 4.43896 | K18: 4.2194 | L18: 4.02255 | M18: 3.84507 | N18: 3.63012 | O18: 3.43458 | P18: 3.25595 | Q18: 3.09214 | R18: 2.94141 | S18: 2.80225 | T18: 2.6734 | U18: 2.55377 | V18: 2.44242 | W18: 2.33852 | X18: 2.24137 | Y18: 2.15033 | Z18: 2.06486 | AA18: 2.01181 | AB18: 1.96051 | AC18: 1.91088 | AD18: 1.86283 | AE18: 1.81631 | AF18: 1.77124 | AG18: 1.72756 | AH18: 1.68521 | AI18: 1.64414 | AJ18: 1.60429 | AK18: 1.56562 | AL18: 1.52807 | AM18: 1.4916 | AN18: 1.45617 | AO18: 1.4129 | AP18: 1.38248 | AQ18: 1.34881 | AR18: 1.31608 | AS18: 1.28423 | AT18: 1.25325 | AU18: 1.2231 | AV18: 1.19376 | AW18: 1.16518 | AX18: 1.13736 | AY18: 1.11025 | AZ18: 1.11025 | BA18: 1.11025 | BB18: 1.11025 | BC18: 1.11025 | BD18: 1.11025 | BE18: 1.11025 | BF18: 1.11025 | BG18: 1.11025 | BH18: 1.11025 | BI18: 1.11025 | BJ18: #N/A | BK18: TRUE
A19: Courbe de charge elec | B19: donnée non utilisée mais vérif de cohérence sur cet onglet | C19: demand_elec | D19: Tertiaire | E19: Base | F19: Final electricity consumption for server equipment (enterprise servers and data centers) | G19: TWh/an | H19: elccftersve | I19: bâtiment_démographie_v2.6 | J19: 7.4 | K19: 7.5 | L19: 7.6 | M19: 7.8 | N19: 8 | O19: 8.2 | P19: 9.5 | Q19: 10.8 | R19: 12.1 | S19: 13.4 | T19: 14.7 | U19: 16 | V19: 17.3 | W19: 18.6 | X19: 19.9 | Y19: 21.2 | Z19: 22.5 | AA19: 23.175 | AB19: 23.6385 | AC19: 23.87488 | AD19: 23.87488 | AE19: 23.87488 | AF19: 23.87488 | AG19: 23.87488 | AH19: 23.87488 | AI19: 23.87488 | AJ19: 23.87488 | AK19: 23.87488 | AL19: 23.87488 | AM19: 23.87488 | AN19: 23.87488 | AO19: 23.87488 | AP19: 23.87488 | AQ19: 23.87488 | AR19: 23.87488 | AS19: 23.87488 | AT19: 23.87488 | AU19: 23.87488 | AV19: 23.87488 | AW19: 23.87488 | AX19: 23.87488 | AY19: 23.87488 | AZ19: 23.87488 | BA19: 23.87488 | BB19: 23.87488 | BC19: 23.87488 | BD19: 23.87488 | BE19: 23.87488 | BF19: 23.87488 | BG19: 23.87488 | BH19: 23.87488 | BI19: 23.87488 | BJ19: #N/A | BK19: TRUE
A20: Courbe de charge elec | B20: donnée non utilisée mais vérif de cohérence sur cet onglet | C20: demand_elec | D20: Tertiaire | E20: Base | F20: Final electricity consumption of the telecom network infrastructure (excl. server equipment) | G20: TWh/an | H20: elccftertni | I20: bâtiment_démographie_v2.6 | J20: 3.56222 | K20: 3.57778 | L20: 3.59333 | M20: 3.60889 | N20: 3.62444 | O20: 3.64 | P20: 3.6764 | Q20: 3.71316 | R20: 3.7503 | S20: 3.7878 | T20: 3.82568 | U20: 3.86393 | V20: 3.90257 | W20: 3.9416 | X20: 3.98101 | Y20: 4.02082 | Z20: 4.06103 | AA20: 4.10164 | AB20: 4.14266 | AC20: 4.18409 | AD20: 4.22593 | AE20: 4.26819 | AF20: 4.31087 | AG20: 4.35398 | AH20: 4.39752 | AI20: 4.44149 | AJ20: 4.48591 | AK20: 4.53077 | AL20: 4.57607 | AM20: 4.62183 | AN20: 4.66805 | AO20: 4.71473 | AP20: 4.76188 | AQ20: 4.8095 | AR20: 4.85759 | AS20: 4.90617 | AT20: 4.95523 | AU20: 5.00478 | AV20: 5.05483 | AW20: 5.10538 | AX20: 5.15643 | AY20: 5.208 | AZ20: 5.208 | BA20: 5.208 | BB20: 5.208 | BC20: 5.208 | BD20: 5.208 | BE20: 5.208 | BF20: 5.208 | BG20: 5.208 | BH20: 5.208 | BI20: 5.208 | BJ20: #N/A | BK20: TRUE
A21: Courbe de charge elec | B21: donnée non utilisée mais vérif de cohérence sur cet onglet | C21: demand_elec | D21: Tertiaire | E21: Base | F21: Final electricity consumption for cold production in the tertiary sector | G21: TWh/an | H21: elccftercol | I21: bâtiment_démographie_v2.6 | J21: 7.75556 | K21: 7.63333 | L21: 7.51111 | M21: 7.38889 | N21: 7.26667 | O21: 7.14444 | P21: 7.02222 | Q21: 7.02222 | R21: 7.02222 | S21: 7.02222 | T21: 7.02222 | U21: 7.02222 | V21: 7.02222 | W21: 7.02222 | X21: 7.02222 | Y21: 7.02222 | Z21: 7.02222 | AA21: 7.02222 | AB21: 7.02222 | AC21: 7.02222 | AD21: 7.02222 | AE21: 7.02222 | AF21: 7.02222 | AG21: 7.02222 | AH21: 7.02222 | AI21: 7.02222 | AJ21: 7.02222 | AK21: 7.02222 | AL21: 7.02222 | AM21: 7.02222 | AN21: 7.02222 | AO21: 7.02222 | AP21: 7.02222 | AQ21: 7.02222 | AR21: 7.02222 | AS21: 7.02222 | AT21: 7.02222 | AU21: 7.02222 | AV21: 7.02222 | AW21: 7.02222 | AX21: 7.02222 | AY21: 7.02222 | AZ21: 7.02222 | BA21: 7.02222 | BB21: 7.02222 | BC21: 7.02222 | BD21: 7.02222 | BE21: 7.02222 | BF21: 7.02222 | BG21: 7.02222 | BH21: 7.02222 | BI21: 7.02222 | BJ21: #N/A | BK21: TRUE
A22: Courbe de charge elec | B22: donnée non utilisée mais vérif de cohérence sur cet onglet | C22: demand_elec | D22: Tertiaire | E22: Base | F22: Final electricity consumption for other activities in the tertiary sector | G22: TWh/an | H22: elccfteroth | I22: bâtiment_démographie_v2.6 | J22: 28.93333 | K22: 28.66667 | L22: 28.4 | M22: 28.13333 | N22: 27.86667 | O22: 27.6 | P22: 27.33333 | Q22: 27.06667 | R22: 26.8 | S22: 26.53333 | T22: 26.26667 | U22: 26 | V22: 25.73333 | W22: 25.46667 | X22: 25.2 | Y22: 24.93333 | Z22: 24.66667 | AA22: 24.4 | AB22: 24.13333 | AC22: 23.86667 | AD22: 23.6 | AE22: 23.33333 | AF22: 23.06667 | AG22: 22.8 | AH22: 22.53333 | AI22: 22.26667 | AJ22: 22 | AK22: 21.73333 | AL22: 21.46667 | AM22: 21.2 | AN22: 21 | AO22: 21 | AP22: 21 | AQ22: 21 | AR22: 21 | AS22: 21 | AT22: 21 | AU22: 21 | AV22: 21 | AW22: 21 | AX22: 21 | AY22: 21 | AZ22: 21 | BA22: 21 | BB22: 21 | BC22: 21 | BD22: 21 | BE22: 21 | BF22: 21 | BG22: 21 | BH22: 21 | BI22: 21 | BJ22: #N/A | BK22: TRUE
A23: Courbe de charge elec | B23: donnée non utilisée mais vérif de cohérence sur cet onglet | C23: demand_elec | D23: Tertiaire | E23: Base | F23: Autre élec spécifique tertiaire (ventilation, portes auto, ascenseurs etc.) | G23: TWh/an | H23: elccfterbmg | I23: bâtiment_démographie_v2.6 | J23: 1.27209 | K23: 1.25814 | L23: 1.24419 | M23: 1.23023 | N23: 1.21628 | O23: 1.20233 | P23: 1.18837 | Q23: 1.17442 | R23: 1.16047 | S23: 1.14651 | T23: 1.13256 | U23: 1.1186 | V23: 1.10465 | W23: 1.0907 | X23: 1.07674 | Y23: 1.06279 | Z23: 1.04884 | AA23: 1.03488 | AB23: 1.02093 | AC23: 1.00698 | AD23: 0.99302 | AE23: 0.97907 | AF23: 0.96512 | AG23: 0.95116 | AH23: 0.93721 | AI23: 0.92326 | AJ23: 0.9093 | AK23: 0.89535 | AL23: 0.8814 | AM23: 0.86744 | AN23: 0.85349 | AO23: 0.83953 | AP23: 0.82558 | AQ23: 0.81163 | AR23: 0.79767 | AS23: 0.78372 | AT23: 0.76977 | AU23: 0.75581 | AV23: 0.74186 | AW23: 0.72791 | AX23: 0.71395 | AY23: 0.7 | AZ23: 0.7 | BA23: 0.7 | BB23: 0.7 | BC23: 0.7 | BD23: 0.7 | BE23: 0.7 | BF23: 0.7 | BG23: 0.7 | BH23: 0.7 | BI23: 0.7 | BJ23: #N/A | BK23: TRUE
A24: Courbe de charge elec | B24: donnée nécessitant un traitement dans traitement_nW_EOLES | C24: demand_elec_ter | D24: Tertiaire | F24: TOTAL | G24: TWh/an | H24: elccfter | I24: bâtiment_démographie_v2.6 | J24: 132.26229 | K24: 130.44511 | L24: 130.96653 | M24: 128.37319 | N24: 125.9242 | O24: 124.73346 | P24: 124.71928 | Q24: 124.89231 | R24: 125.10709 | S24: 125.35972 | T24: 125.6437 | U24: 125.90615 | V24: 126.04473 | W24: 126.12381 | X24: 126.11973 | Y24: 126.03112 | Z24: 125.85622 | AA24: 125.08547 | AB24: 124.16555 | AC24: 122.93387 | AD24: 121.45976 | AE24: 119.92399 | AF24: 118.5809 | AG24: 117.23578 | AH24: 115.89638 | AI24: 114.57101 | AJ24: 113.27213 | AK24: 111.97674 | AL24: 110.69165 | AM24: 109.42565 | AN24: 108.31191 | AO24: 107.40139 | AP24: 106.85822 | AQ24: 106.34409 | AR24: 105.87724 | AS24: 105.45646 | AT24: 105.07907 | AU24: 104.74643 | AV24: 104.45298 | AW24: 104.18982 | AX24: 103.95221 | AY24: 103.73578 | AZ24: 103.54489 | BA24: 103.36613 | BB24: 103.19657 | BC24: 103.03379 | BD24: 102.8749 | BE24: 102.71595 | BF24: 102.55892 | BG24: 102.40881 | BH24: 102.28406 | BI24: 102.152
A25: Courbe de charge elec | B25: donnée non utilisée mais vérif de cohérence sur cet onglet | C25: demand_elec | D25: Tertiaire | F25: DELTA TOTAL vs. somme | G25: TWh/an | J25: =J24-SUM(J11:J23) -> 0 | K25: =K24-SUM(K11:K23) -> 0 | L25: =L24-SUM(L11:L23) -> -1e-05 | M25: =M24-SUM(M11:M23) -> -1e-05 | N25: =N24-SUM(N11:N23) -> 0 | O25: =O24-SUM(O11:O23) -> 0 | P25: =P24-SUM(P11:P23) -> 1e-05 | Q25: =Q24-SUM(Q11:Q23) -> 2e-05 | ... BI25: =BI24-SUM(BI11:BI23) -> 1e-05
A27: Courbe de charge elec | B27: donnée non utilisée mais vérif de cohérence sur cet onglet | C27: demand_elec | D27: Mobilité domestique | F27: Mobilité - VP | G27: TWh/an | H27: elccfmobvp | I27: transports_v6.13 | J27: 0.33091 | K27: 0.42852 | L27: 0.80105 | M27: 1.42728 | N27: 1.99158 | O27: 2.84853 | P27: 4.09331 | Q27: 5.1722 | R27: 6.5855 | S27: 8.06723 | T27: 9.78761 | U27: 11.91067 | V27: 14.2006 | W27: 16.37184 | X27: 18.63486 | Y27: 20.8421 | Z27: 23.0201 | AA27: 25.15144 | AB27: 27.44936 | AC27: 29.71927 | AD27: 31.9794 | AE27: 34.24092 | AF27: 36.63668 | AG27: 39.00934 | AH27: 41.27006 | AI27: 43.32919 | AJ27: 45.10003 | AK27: 46.63773 | AL27: 47.86858 | AM27: 48.80693 | AN27: 49.47819 | AO27: 49.67895 | AP27: 49.6764 | AQ27: 49.65556 | AR27: 49.63102 | AS27: 49.60264 | AT27: 49.57077 | AU27: 49.53587 | AV27: 49.49845 | AW27: 49.459 | AX27: 49.41809 | AY27: 49.37652 | AZ27: 49.33507 | BA27: 49.29393 | BB27: 49.25373 | BC27: 49.21503 | BD27: 49.17813 | BE27: 49.14339 | BF27: 49.11086 | BG27: 49.08059 | BH27: 49.05262 | BI27: 49.02316 | BJ27: #N/A | BK27: TRUE
A28: Courbe de charge elec | B28: donnée non utilisée mais vérif de cohérence sur cet onglet | C28: demand_elec | D28: Mobilité domestique | F28: Mobilité - autres (bus, 2RM, vélos, train/metro/tram) | G28: TWh/an | H28: elccfmobautre | I28: transports_v6.13 | J28: 8.70587 | K28: 5.0253 | L28: 6.59833 | M28: 8.93174 | N28: 9.4797 | O28: 10.11228 | P28: 10.43964 | Q28: 10.53455 | R28: 10.63075 | S28: 10.67003 | T28: 10.71177 | U28: 10.76048 | V28: 10.86162 | W28: 11.02246 | X28: 11.32383 | Y28: 11.64611 | Z28: 11.98696 | AA28: 12.34842 | AB28: 12.72236 | AC28: 13.10345 | AD28: 13.48687 | AE28: 13.87792 | AF28: 14.21473 | AG28: 14.53928 | AH28: 14.84961 | AI28: 15.14502 | AJ28: 15.43686 | AK28: 15.71599 | AL28: 15.98431 | AM28: 16.24431 | AN28: 16.49859 | AO28: 16.80042 | AP28: 16.80497 | AQ28: 16.78092 | AR28: 16.75208 | AS28: 16.71814 | AT28: 16.75368 | AU28: 16.6327 | AV28: 16.70825 | AW28: 16.78553 | AX28: 16.86488 | AY28: 16.94679 | AZ28: 16.99115 | BA28: 17.00702 | BB28: 17.02363 | BC28: 17.04103 | BD28: 17.05935 | BE28: 17.07871 | BF28: 17.09917 | BG28: 17.12073 | BH28: 17.14344 | BI28: 17.16583 | BJ28: #N/A | BK28: TRUE
A29: Courbe de charge elec | B29: donnée nécessitant un traitement dans traitement_nW_EOLES | C29: demand_elec_mob | D29: Mobilité domestique | F29: TOTAL | G29: TWh/an | H29: elccfmob | I29: transports_v6.13 | J29: 9.03678 | K29: 5.45382 | L29: 7.39938 | M29: 10.35901 | N29: 11.47128 | O29: 12.96082 | P29: 14.53295 | Q29: 15.70675 | R29: 17.21625 | S29: 18.73726 | T29: 20.49937 | U29: 22.67115 | V29: 25.06221 | W29: 27.3943 | X29: 29.9587 | Y29: 32.4882 | Z29: 35.00706 | AA29: 37.49986 | AB29: 40.17172 | AC29: 42.82273 | AD29: 45.46627 | AE29: 48.11884 | AF29: 50.85142 | AG29: 53.54862 | AH29: 56.11967 | AI29: 58.47421 | AJ29: 60.53689 | AK29: 62.35372 | AL29: 63.85289 | AM29: 65.05123 | AN29: 65.97678 | AO29: 66.47937 | AP29: 66.48137 | AQ29: 66.43648 | AR29: 66.3831 | AS29: 66.32078 | AT29: 66.32445 | AU29: 66.16857 | AV29: 66.2067 | AW29: 66.24452 | AX29: 66.28297 | AY29: 66.32331 | AZ29: 66.32622 | BA29: 66.30095 | BB29: 66.27736 | BC29: 66.25606 | BD29: 66.23748 | BE29: 66.22211 | BF29: 66.21002 | BG29: 66.20132 | BH29: 66.19606 | BI29: 66.18899 | BJ29: Consommation finale d'électricité liée à la mobilité des passagers
A30: Courbe de charge elec | B30: donnée non utilisée mais vérif de cohérence sur cet onglet | C30: demand_elec | D30: Mobilité domestique | F30: DELTA TOTAL vs. somme | G30: TWh/an | J30: =J29-SUM(J27:J28) -> 0 | K30: =K29-SUM(K27:K28) -> 0 | L30: =L29-SUM(L27:L28) -> 0 | M30: =M29-SUM(M27:M28) -> -1e-05 | N30: =N29-SUM(N27:N28) -> 0 | O30: =O29-SUM(O27:O28) -> 1e-05 | P30: =P29-SUM(P27:P28) -> 0 | Q30: =Q29-SUM(Q27:Q28) -> 0 | ... BI30: =BI29-SUM(BI27:BI28) -> 0
A32: Courbe de charge elec | B32: donnée non utilisée mais vérif de cohérence sur cet onglet | C32: demand_elec | D32: Fret domestique | F32: Fret - VUL | G32: TWh/an | H32: elccffrevul | I32: transports_v6.13 | J32: 0.15168 | K32: 0.15521 | L32: 0.20528 | M32: 0.24436 | N32: 0.30068 | O32: 0.4019 | P32: 0.74608 | Q32: 0.96025 | R32: 1.27948 | S32: 1.79065 | T32: 2.53908 | U32: 3.5019 | V32: 4.66792 | W32: 6.00502 | X32: 7.51452 | Y32: 9.15558 | Z32: 10.90089 | AA32: 12.69927 | AB32: 14.49647 | AC32: 16.23754 | AD32: 17.90587 | AE32: 19.48413 | AF32: 20.95375 | AG32: 22.29544 | AH32: 23.49163 | AI32: 24.52919 | AJ32: 25.40202 | AK32: 26.11208 | AL32: 26.66886 | AM32: 27.08807 | AN32: 27.38971 | AO32: 27.59603 | AP32: 27.72931 | AQ32: 27.81017 | AR32: 27.85593 | AS32: 27.87995 | AT32: 27.89158 | AU32: 27.89676 | AV32: 27.89885 | AW32: 27.89964 | AX32: 27.89989 | AY32: 27.89997 | AZ32: 27.9 | BA32: 27.9 | BB32: 27.9 | BC32: 27.9 | BD32: 27.9 | BE32: 27.9 | BF32: 27.9 | BG32: 27.9 | BH32: 27.9 | BI32: 27.9 | BJ32: #N/A | BK32: TRUE
A33: Courbe de charge elec | B33: donnée non utilisée mais vérif de cohérence sur cet onglet | C33: demand_elec | D33: Fret domestique | F33: Fret - PL (FR et étrangers) | G33: TWh/an | H33: elccffrepl | I33: transports_v6.13 | J33: 0.01518 | K33: 0.0131 | L33: 0.0158 | M33: 0.01674 | N33: 0.01659 | O33: 0.0627 | P33: 0.34061 | Q33: 0.42522 | R33: 0.53585 | S33: 0.68543 | T33: 0.88475 | U33: 1.15024 | V33: 1.47251 | W33: 1.83732 | X33: 2.40103 | Y33: 3.08007 | Z33: 3.92107 | AA33: 4.91903 | AB33: 5.995 | AC33: 7.12954 | AD33: 8.32036 | AE33: 9.56645 | AF33: 10.90376 | AG33: 12.30166 | AH33: 13.71185 | AI33: 15.04574 | AJ33: 16.19688 | AK33: 17.13563 | AL33: 17.7782 | AM33: 18.15199 | AN33: 18.31392 | AO33: 18.32482 | AP33: 18.26522 | AQ33: 18.20407 | AR33: 18.14139 | AS33: 18.07719 | AT33: 18.01148 | AU33: 17.90103 | AV33: 17.78938 | AW33: 17.67655 | AX33: 17.5626 | AY33: 17.44754 | AZ33: 17.46454 | BA33: 17.48076 | BB33: 17.4962 | BC33: 17.51089 | BD33: 17.52485 | BE33: 17.48694 | BF33: 17.44914 | BG33: 17.41143 | BH33: 17.37383 | BI33: 17.33632 | BJ33: #N/A | BK33: TRUE
A34: Courbe de charge elec | B34: donnée non utilisée mais vérif de cohérence sur cet onglet | C34: demand_elec | D34: Fret domestique | F34: Fret - ferroviaire | G34: TWh/an | H34: elccffrefer | I34: transports_v6.13 | J34: 1.09838 | K34: 1.01328 | L34: 1.15731 | M34: 1.14042 | N34: 0.98004 | O34: 1.05085 | P34: 1.05833 | Q34: 1.05622 | R34: 1.05256 | S34: 1.11198 | T34: 1.14794 | U34: 1.18187 | V34: 1.21552 | W34: 1.2474 | X34: 1.27769 | Y34: 1.30661 | Z34: 1.33442 | AA34: 1.36141 | AB34: 1.38786 | AC34: 1.41402 | AD34: 1.44008 | AE34: 1.4662 | AF34: 1.496 | AG34: 1.52612 | AH34: 1.55652 | AI34: 1.58713 | AJ34: 1.61786 | AK34: 1.6486 | AL34: 1.67925 | AM34: 1.70971 | AN34: 1.73992 | AO34: 1.7693 | AP34: 1.80679 | AQ34: 1.84413 | AR34: 1.88133 | AS34: 1.91838 | AT34: 1.95418 | AU34: 1.98356 | AV34: 2.01243 | AW34: 2.04062 | AX34: 2.06793 | AY34: 2.0941 | AZ34: 2.08583 | BA34: 2.07612 | BB34: 2.06475 | BC34: 2.0515 | BD34: 2.03625 | BE34: 2.01894 | BF34: 1.99967 | BG34: 1.97862 | BH34: 1.95612 | BI34: 1.93262 | BJ34: #N/A | BK34: TRUE
A35: Courbe de charge elec | B35: donnée nécessitant un traitement dans traitement_nW_EOLES | C35: demand_elec_fret | D35: Fret domestique | F35: TOTAL | G35: TWh/an | H35: elccffre | I35: transports_v6.13 | J35: 1.26524 | K35: 1.18159 | L35: 1.37839 | M35: 1.40152 | N35: 1.29731 | O35: 1.51545 | P35: 2.14502 | Q35: 2.4417 | R35: 2.86789 | S35: 3.58807 | T35: 4.57177 | U35: 5.83401 | V35: 7.35594 | W35: 9.08974 | X35: 11.19324 | Y35: 13.54226 | Z35: 16.15638 | AA35: 18.97972 | AB35: 21.87932 | AC35: 24.7811 | AD35: 27.66631 | AE35: 30.51678 | AF35: 33.35351 | AG35: 36.12322 | AH35: 38.75999 | AI35: 41.16207 | AJ35: 43.21676 | AK35: 44.89631 | AL35: 46.12631 | AM35: 46.94977 | AN35: 47.44354 | AO35: 47.69015 | AP35: 47.80131 | AQ35: 47.85837 | AR35: 47.87864 | AS35: 47.87552 | AT35: 47.85724 | AU35: 47.78134 | AV35: 47.70066 | AW35: 47.61681 | AX35: 47.53042 | AY35: 47.44162 | AZ35: 47.45037 | BA35: 47.45688 | BB35: 47.46095 | BC35: 47.46239 | BD35: 47.46109 | BE35: 47.40588 | BF35: 47.3488 | BG35: 47.29005 | BH35: 47.22995 | BI35: 47.16894 | BJ35: Consommation finale d'électricité dans le transport de marchandises
A36: Courbe de charge elec | B36: donnée non utilisée mais vérif de cohérence sur cet onglet | C36: demand_elec | D36: Fret domestique | F36: DELTA TOTAL vs. somme | G36: TWh/an | J36: =J35-SUM(J32:J34) -> 0 | K36: =K35-SUM(K32:K34) -> 0 | L36: =L35-SUM(L32:L34) -> 0 | M36: =M35-SUM(M32:M34) -> 0 | N36: =N35-SUM(N32:N34) -> 0 | O36: =O35-SUM(O32:O34) -> 0 | P36: =P35-SUM(P32:P34) -> 0 | Q36: =Q35-SUM(Q32:Q34) -> 1e-05 | ... BI36: =BI35-SUM(BI32:BI34) -> 0
A38: Courbe de charge elec | B38: donnée nécessitant un traitement dans traitement_nW_EOLES | C38: demand_elec_agr | D38: Agriculture | F38: Conso d'élec de l'agriculture | G38: TWh/an | H38: elccfagr | I38: agriculture_v5 | J38: 8.47942 | K38: 8.07949 | L38: 7.64995 | M38: 7.88962 | N38: 7.14746 | O38: 7.14746 | P38: 7.89465 | Q38: 8.01921 | R38: 8.16312 | S38: 8.32483 | T38: 8.50255 | U38: 8.69435 | V38: 8.89811 | W38: 9.11161 | X38: 9.3325 | Y38: 9.55838 | Z38: 9.78675 | AA38: 10.01512 | AB38: 10.241 | AC38: 10.46189 | AD38: 10.67539 | AE38: 10.87915 | AF38: 11.07094 | AG38: 11.24867 | AH38: 11.41037 | AI38: 11.55429 | AJ38: 11.67884 | AK38: 11.78267 | AL38: 11.86462 | AM38: 11.92381 | AN38: 11.95958 | AO38: 11.97155 | AP38: 11.97454 | AQ38: 11.98343 | AR38: 11.99801 | AS38: 12.01791 | AT38: 12.04265 | AU38: 12.07162 | AV38: 12.1041 | AW38: 12.13929 | AX38: 12.17633 | AY38: 12.21431 | AZ38: 12.25228 | BA38: 12.28932 | BB38: 12.32452 | BC38: 12.357 | BD38: 12.38596 | BE38: 12.4107 | BF38: 12.43061 | BG38: 12.44518 | BH38: 12.45408 | BI38: 12.45706 | BJ38: #N/A | BK38: TRUE
A39: Courbe de charge elec | B39: donnée nécessitant un traitement dans traitement_nW_EOLES | C39: demand_elec_ind | D39: Industrie manufacturière | E39: Pro | F39: Conso d'élec de l'industrie | G39: TWh/an | H39: elccfind | I39: industrie | J39: 111.6186 | K39: 101.63997 | L39: 107.66192 | M39: 104.69555 | N39: 102.81144 | O39: 101.68124 | P39: 102.20269 | Q39: 103.11652 | R39: 104.56324 | S39: 106.34312 | T39: 108.05253 | U39: 109.46302 | V39: 110.74475 | W39: 111.86779 | X39: 112.92387 | Y39: 113.99316 | Z39: 114.07532 | AA39: 114.69562 | AB39: 115.34976 | AC39: 115.68589 | AD39: 115.82046 | AE39: 112.69467 | AF39: 113.26553 | AG39: 113.36708 | AH39: 114.39086 | AI39: 114.52518 | AJ39: 115.20246 | AK39: 115.6797 | AL39: 116.23297 | AM39: 116.65812 | AN39: 116.71588 | AO39: 116.83425 | AP39: 116.24859 | AQ39: 115.87599 | AR39: 114.84787 | AS39: 114.6957 | AT39: 114.60027 | AU39: 114.09647 | AV39: 113.83748 | AW39: 114.01311 | AX39: 114.10024 | AY39: 113.93828 | AZ39: 114.53557 | BA39: 114.11485 | BB39: 114.22638 | BC39: 113.15087 | BD39: 113.63445 | BE39: 112.95177 | BF39: 112.96351 | BG39: 112.27905 | BH39: 112.59247 | BI39: 112.07422 | BJ39: Électricité | BK39: TRUE
A40: Courbe de charge elec | B40: donnée non utilisée mais vérif de cohérence avec sorties | C40: demand_elec | D40: Electrolyse | F40: Conso d'élec pour production H2 | G40: TWh/an | H40: sec_uses.elc_se.hyd_se | I40: SEPIA | J40: 0 | K40: 0 | L40: 0 | M40: 0 | N40: 0 | O40: 0 | P40: 0 | Q40: 1.5384 | R40: 3.1536 | S40: 4.7304 | T40: 6.3072 | U40: 7.884 | V40: 10.3368 | W40: 12.7021 | X40: 14.9796 | Y40: 17.1697 | Z40: 19.2719 | AA40: 24.5979 | AB40: 29.7138 | AC40: 34.6197 | AD40: 39.3151 | AE40: 43.8002 | AF40: 49.792 | AG40: 55.5035 | AH40: 60.9341 | AI40: 66.085 | AJ40: 70.9559 | AK40: 77.8594 | AL40: 84.3766 | AM40: 90.5087 | AN40: 96.2544 | AO40: 101.6156 | AP40: 102.6677 | AQ40: 103.7185 | AR40: 104.7692 | AS40: 105.8214 | AT40: 106.872 | AU40: 107.9236 | AV40: 108.9749 | AW40: 110.0259 | AX40: 111.0763 | AY40: 112.1276 | AZ40: 112.8291 | BA40: 113.5293 | BB40: 114.2305 | BC40: 114.9313 | BD40: 115.6321 | BE40: 116.3323 | BF40: 117.033 | BG40: 117.7347 | BH40: 118.4344 | BI40: 119.1367 | BJ40: #N/A | BK40: TRUE
A41: Courbe de charge elec | B41: donnée nécessitant un traitement dans traitement_nW_EOLES | C41: demand_elec_neth | D41: Branche énergie de l'industrie | F41: Conso d'élec pour réseaux de chaleur (PAC, P2H...) | G41: TWh/an | H41: sec_uses.elc_se.vap_se | I41: SEPIA | J41: 0.2532 | K41: 0.2532 | L41: 0.3391 | M41: 0.5017 | N41: 0.5696 | O41: 0.6442 | P41: 0.7189 | Q41: 0.7223 | R41: 0.7252 | S41: 0.7276 | T41: 0.7296 | U41: 0.75 | V41: 0.9284 | W41: 1.1446 | X41: 1.3998 | Y41: 1.7188 | Z41: 2.0313 | AA41: 2.2759 | AB41: 2.4944 | AC41: 2.7109 | AD41: 2.8543 | AE41: 2.9212 | AF41: 2.9879 | AG41: 3.0545 | AH41: 3.1212 | AI41: 3.1879 | AJ41: 3.2545 | AK41: 3.2545 | AL41: 3.2545 | AM41: 3.2545 | AN41: 3.2545 | AO41: 3.2545 | AP41: 3.2545 | AQ41: 3.2545 | AR41: 3.2545 | AS41: 3.2545 | AT41: 3.2545 | AU41: 3.2545 | AV41: 3.2545 | AW41: 3.2545 | AX41: 3.2545 | AY41: 3.2545 | AZ41: 3.2545 | BA41: 3.2545 | BB41: 3.2545 | BC41: 3.2545 | BD41: 3.2545 | BE41: 3.2545 | BF41: 3.2545 | BG41: 3.2545 | BH41: 3.2545 | BI41: 3.2545 | BJ41: #N/A | BK41: TRUE
A42: Courbe de charge elec | B42: donnée nécessitant un traitement dans traitement_nW_EOLES | C42: demand_elec_other | D42: Branche énergie de l'industrie | F42: Autre conso d'élec de la branche énergie (raffineries…) | G42: TWh/an | H42: sec_uses.elc_se.ens | I42: SEPIA | J42: 9.4734 | K42: 8.2468 | L42: 8.5828 | M42: 9.1784 | N42: 9.1257 | O42: 9.0529 | P42: 9.3541 | Q42: 9.7113 | R42: 10.1042 | S42: 10.4642 | T42: 10.8655 | U42: 11.4625 | V42: 12.0109 | W42: 12.5895 | X42: 13.2082 | Y42: 13.8502 | Z42: 14.4703 | AA42: 15.0957 | AB42: 15.7211 | AC42: 16.3252 | AD42: 16.8922 | AE42: 17.3968 | AF42: 17.9083 | AG42: 18.3949 | AH42: 18.8579 | AI42: 19.3463 | AJ42: 19.759 | AK42: 20.174 | AL42: 20.6698 | AM42: 21.1644 | AN42: 21.6228 | AO42: 22.0575 | AP42: 21.8699 | AQ42: 21.6802 | AR42: 21.4882 | AS42: 21.3759 | AT42: 21.1796 | AU42: 21.1412 | AV42: 21.1098 | AW42: 21.0755 | AX42: 20.9899 | AY42: 20.9709 | AZ42: 20.969 | BA42: 20.9655 | BB42: 20.9626 | BC42: 20.9633 | BD42: 20.9613 | BE42: 20.9589 | BF42: 20.9573 | BG42: 20.9544 | BH42: 20.9502 | BI42: 20.9477 | BJ42: #N/A | BK42: TRUE
A43: Courbe de charge elec | B43: donnée non utilisée mais vérif de cohérence avec sorties | C43: demand_elec | D43: Pertes | F43: Pertes liées au stockage (batteries, STEP) | G43: TWh/an | H43: sec_uses.elc_se.sto_se | I43: SEPIA | J43: 1.795 | K43: 1.7554 | L43: 1.6373 | M43: 1.9913 | N43: 1.6212 | O43: 2.065 | P43: 2.065 | Q43: 2.065 | R43: 2.065 | S43: 2.065 | T43: 2.065 | U43: 2.065 | V43: 2.065 | W43: 2.065 | X43: 2.065 | Y43: 2.065 | Z43: 2.065 | AA43: 2.065 | AB43: 2.065 | AC43: 2.065 | AD43: 2.065 | AE43: 2.065 | AF43: 2.065 | AG43: 2.065 | AH43: 2.065 | AI43: 2.065 | AJ43: 2.065 | AK43: 2.065 | AL43: 2.065 | AM43: 2.065 | AN43: 2.065 | AO43: 2.065 | AP43: 2.065 | AQ43: 2.065 | AR43: 2.065 | AS43: 2.065 | AT43: 2.065 | AU43: 2.065 | AV43: 2.065 | AW43: 2.065 | AX43: 2.065 | AY43: 2.065 | AZ43: 2.065 | BA43: 2.065 | BB43: 2.065 | BC43: 2.065 | BD43: 2.065 | BE43: 2.065 | BF43: 2.065 | BG43: 2.065 | BH43: 2.065 | BI43: 2.065 | BJ43: #N/A | BK43: TRUE
A44: Courbe de charge elec | B44: donnée non utilisée mais vérif de cohérence avec sorties | C44: demand_elec | D44: Excédents | F44: Excédents | G44: TWh/an | H44: sec_uses.elc_se.exp | I44: SEPIA | J44: 63.682 | K44: 51.3818 | L44: 63.5099 | M44: 0 | N44: 54.2261 | O44: 99.2347 | P44: 108.7035 | Q44: 114.2355 | R44: 107.1213 | S44: 105.6057 | T44: 119.3642 | U44: 98.1384 | V44: 81.8314 | W44: 95.5186 | X44: 86.2619 | Y44: 78.164 | Z44: 75.2403 | AA44: 74.8837 | AB44: 71.5464 | AC44: 71.245 | AD44: 92.6629 | AE44: 88.577 | AF44: 80.0542 | AG44: 70.3994 | AH44: 43.415 | AI44: 51.3645 | AJ44: 59.4076 | AK44: 51.9256 | AL44: 59.2221 | AM44: 44.0117 | AN44: 52.9166 | AO44: 40.4532 | AP44: 52.5081 | AQ44: 61.6219 | AR44: 45.6705 | AS44: 56.6618 | AT44: 64.0294 | AU44: 67.6545 | AV44: 64.5227 | AW44: 56.6648 | AX44: 61.1764 | AY44: 58.3952 | AZ44: 69.0732 | BA44: 79.285 | BB44: 72.378 | BC44: 74.9072 | BD44: 84.8105 | BE44: 88.4367 | BF44: 91.2742 | BG44: 93.9498 | BH44: 95.391 | BI44: 97.0218 | BJ44: #N/A | BK44: TRUE
...

Sheet traitement_nW_EOLES
A1: code EOLES | B1: Descriptif | C1: Valeur | D1: Usage
B4: correction climat chauffage | C4: -0.07
B5: correction climat clim | C5: 0.6
B7: Demande élec
A9: demand_elec_res_heat | B9: Chauffage résidentiel | C9: {=INDEX(Data_EOLES!$J$1:$EK$191,MATCH(A9,Data_EOLES!$C:$C,0),MATCH(year_simulated,VALUE(Data_EOLES!$J$1:$EK$1),0))} -> 27.61632 | D9: dans cette feuille
A10: demand_elec_ter_heat | B10: Chauffage tertiaire | C10: {=INDEX(Data_EOLES!$J$1:$EK$191,MATCH(A10,Data_EOLES!$C:$C,0),MATCH(year_simulated,VALUE(Data_EOLES!$J$1:$EK$1),0))} -> 7.67608 | D10: dans cette feuille
A11: demand_elec_res_cool | B11: Clim résidentiel | C11: {=INDEX(Data_EOLES!$J$1:$EK$191,MATCH(A11,Data_EOLES!$C:$C,0),MATCH(year_simulated,VALUE(Data_EOLES!$J$1:$EK$1),0))} -> 3.34028 | D11: Pas utilisé ?
A12: demand_elec_ter_cool | B12: Clim tertiaire | C12: {=INDEX(Data_EOLES!$J$1:$EK$191,MATCH(A12,Data_EOLES!$C:$C,0),MATCH(year_simulated,VALUE(Data_EOLES!$J$1:$EK$1),0))} -> 16.65179 | D12: Pas utilisé ?
A14: demand_elec_res | B14: Total résidentiel | C14: {=INDEX(Data_EOLES!$J$1:$EK$191,MATCH(A14,Data_EOLES!$C:$C,0),MATCH(year_simulated,VALUE(Data_EOLES!$J$1:$EK$1),0))} -> 96.29877 | D14: dans cette feuille
A15: demand_elec_ter | B15: Total tertaire | C15: {=INDEX(Data_EOLES!$J$1:$EK$191,MATCH(A15,Data_EOLES!$C:$C,0),MATCH(year_simulated,VALUE(Data_EOLES!$J$1:$EK$1),0))} -> 103.73578 | D15: dans cette feuille
A16: demand_elec_mob | B16: Total mobilité | C16: {=INDEX(Data_EOLES!$J$1:$EK$191,MATCH(A16,Data_EOLES!$C:$C,0),MATCH(year_simulated,VALUE(Data_EOLES!$J$1:$EK$1),0))} -> 66.32331 | D16: dans cette feuille
A17: demand_elec_fret | B17: Total frêt | C17: {=INDEX(Data_EOLES!$J$1:$EK$191,MATCH(A17,Data_EOLES!$C:$C,0),MATCH(year_simulated,VALUE(Data_EOLES!$J$1:$EK$1),0))} -> 47.44162 | D17: dans cette feuille
A18: demand_elec_ind | B18: Total industrie | C18: {=INDEX(Data_EOLES!$J$1:$EK$191,MATCH(A18,Data_EOLES!$C:$C,0),MATCH(year_simulated,VALUE(Data_EOLES!$J$1:$EK$1),0))} -> 113.93828 | D18: dans cette feuille
A19: demand_elec_agr | B19: Total agriculture | C19: {=INDEX(Data_EOLES!$J$1:$EK$191,MATCH(A19,Data_EOLES!$C:$C,0),MATCH(year_simulated,VALUE(Data_EOLES!$J$1:$EK$1),0))} -> 12.21431 | D19: dans cette feuille
A20: demand_elec_other | B20: Total autre énergie | C20: {=INDEX(Data_EOLES!$J$1:$EK$191,MATCH(A20,Data_EOLES!$C:$C,0),MATCH(year_simulated,VALUE(Data_EOLES!$J$1:$EK$1),0))} -> 20.9709 | D20: dans cette feuille
A21: demand_elec_neth | B21: Total chaleur | C21: {=INDEX(Data_EOLES!$J$1:$EK$191,MATCH(A21,Data_EOLES!$C:$C,0),MATCH(year_simulated,VALUE(Data_EOLES!$J$1:$EK$1),0))} -> 3.2545 | D21: dans cette feuille
A22: demand_elec_losses | B22: Pertes réseau (transport & distribution) | C22: {=INDEX(Data_EOLES!$J$1:$EK$191,MATCH(A22,Data_EOLES!$C:$C,0),MATCH(year_simulated,VALUE(Data_EOLES!$J$1:$EK$1),0))} -> 39.9809 | D22: dans cette feuille
A24: demand_elec_tot | B24: Total elec | C24: =SUM(C14:C22) -> 504.15837 | D24: create_demand_param
B25: ="Total chauffage elec " &year_simulated -> Total chauffage elec 2060 | C25: =SUM(C9:C10) -> 35.2924 | D25: dans cette feuille
B26: Total chauffage elec 2019 corrigé climat 2050 | C26: =C27*(1+C4) -> 67.162163
B27: Total chauffage elec 2019 | C27: {=INDEX(Data_EOLES!$J$1:$EK$191,MATCH($A9,Data_EOLES!$C:$C,0),MATCH(2019,VALUE(Data_EOLES!$J$1:$EK$1),0)) + INDEX(Data_EOLES!$J$1:$EK$191,MATCH($A10,Data_EOLES!$C:$C,0),MATCH(2019,VALUE(Data_EOLES!$J$1:$EK$1),0))} -> 72.21738 | D27: dans cette feuille
B28: Total clim elec 2050 | C28: =SUM(C11:C12) -> 19.99207
B29: Total clim elec 2019 corrigé climat 2050 | C29: =C30*(1+C5) -> 25.846464
B30: Total clim elec 2019 | C30: {=INDEX(Data_EOLES!$J$1:$EK$191,MATCH($A11,Data_EOLES!$C:$C,0),MATCH(2019,VALUE(Data_EOLES!$J$1:$EK$1),0)) + INDEX(Data_EOLES!$J$1:$EK$191,MATCH($A12,Data_EOLES!$C:$C,0),MATCH(2019,VALUE(Data_EOLES!$J$1:$EK$1),0))} -> 16.15404
A31: coef_elec | B31: ="coef elec 2019 "&year_simulated -> coef elec 2019 2060 | C31: =C25/C26 -> 0.52548039 | D31: create_demand_param
A32: coef_clim_elec | B32: coef clim 2019 2050 | C32: =C28/C29 -> 0.77349343 | D32: create_demand_param
B34: Demande gaz (TWh PCI)
A36: demand_CH4_res_heat | B36: Chauffage résidentiel | C36: {=INDEX(Data_EOLES!$J$1:$EK$191,MATCH(A36,Data_EOLES!$C:$C,0),MATCH(year_simulated,VALUE(Data_EOLES!$J$1:$EK$1),0))} -> 14.93263 | D36: dans cette feuille
A37: demand_CH4_ter_heat | B37: Chauffage tertiaire | C37: {=INDEX(Data_EOLES!$J$1:$EK$191,MATCH(A37,Data_EOLES!$C:$C,0),MATCH(year_simulated,VALUE(Data_EOLES!$J$1:$EK$1),0))} -> 6.40148 | D37: dans cette feuille
A41: demand_CH4_res | B41: Total résidentiel | C41: {=INDEX(Data_EOLES!$J$1:$EK$191,MATCH(A41,Data_EOLES!$C:$C,0),MATCH(year_simulated,VALUE(Data_EOLES!$J$1:$EK$1),0))} -> 17.133 | D41: dans cette feuille
A42: demand_CH4_ter | B42: Total tertaire | C42: {=INDEX(Data_EOLES!$J$1:$EK$191,MATCH(A42,Data_EOLES!$C:$C,0),MATCH(year_simulated,VALUE(Data_EOLES!$J$1:$EK$1),0))} -> 10.39766 | D42: dans cette feuille
A43: demand_CH4_mob | B43: Total mobilité | C43: {=INDEX(Data_EOLES!$J$1:$EK$191,MATCH(A43,Data_EOLES!$C:$C,0),MATCH(year_simulated,VALUE(Data_EOLES!$J$1:$EK$1),0))} -> 6.0953 | D43: dans cette feuille
A44: demand_CH4_fret | B44: Total frêt | C44: {=INDEX(Data_EOLES!$J$1:$EK$191,MATCH(A44,Data_EOLES!$C:$C,0),MATCH(year_simulated,VALUE(Data_EOLES!$J$1:$EK$1),0))} -> 22.76362 | D44: dans cette feuille
A45: demand_CH4_ind | B45: Total industrie | C45: {=INDEX(Data_EOLES!$J$1:$EK$191,MATCH(A45,Data_EOLES!$C:$C,0),MATCH(year_simulated,VALUE(Data_EOLES!$J$1:$EK$1),0))} -> 42.38283 | D45: dans cette feuille
A46: demand_CH4_agr | B46: Total agriculture | C46: {=INDEX(Data_EOLES!$J$1:$EK$191,MATCH(A46,Data_EOLES!$C:$C,0),MATCH(year_simulated,VALUE(Data_EOLES!$J$1:$EK$1),0))} -> 10.57793 | D46: dans cette feuille
A47: demand_CH4_raf | B47: Total autre énergie | C47: {=INDEX(Data_EOLES!$J$1:$EK$191,MATCH(A47,Data_EOLES!$C:$C,0),MATCH(year_simulated,VALUE(Data_EOLES!$J$1:$EK$1),0))} -> 2.9595 | D47: dans cette feuille
B48: Total chaleur cogé gaz | C48: 2 | D48: lecture Sankey
A49: demand_CH4_neth | B49: Total chaleur | C49: {=INDEX(Data_EOLES!$J$1:$EK$191,MATCH(A49,Data_EOLES!$C:$C,0),MATCH(year_simulated,VALUE(Data_EOLES!$J$1:$EK$1),0))} -> 5.0358 | D49: dans cette feuille
A50: demand_CH4_other | B50: Total non-énergétique | C50: {=INDEX(Data_EOLES!$J$1:$EK$191,MATCH(A50,Data_EOLES!$C:$C,0),MATCH(year_simulated,VALUE(Data_EOLES!$J$1:$EK$1),0))} -> 7.85429 | D50: dans cette feuille
A51: demand_CH4_mar | B51: Total transport maritime international | C51: {=INDEX(Data_EOLES!$J$1:$EK$191,MATCH(A51,Data_EOLES!$C:$C,0),MATCH(year_simulated,VALUE(Data_EOLES!$J$1:$EK$1),0))} -> 3.01575 | D51: dans cette feuille
...

Sheet create_demand_param
A1: demand_elec_tot | B1: =INDEX(traitement_nW_EOLES!$C:$C,MATCH($A1,traitement_nW_EOLES!$A:$A,0)) -> 504.15837
A2: coef_elec | B2: =INDEX(traitement_nW_EOLES!$C:$C,MATCH($A2,traitement_nW_EOLES!$A:$A,0)) -> 0.52548039
A3: coef_clim_elec | B3: =INDEX(traitement_nW_EOLES!$C:$C,MATCH($A3,traitement_nW_EOLES!$A:$A,0)) -> 0.77349343
A4: demand_CH4_tot | B4: =INDEX(traitement_nW_EOLES!$C:$C,MATCH($A4,traitement_nW_EOLES!$A:$A,0)) -> 127.44288
A5: coef_CH4 | B5: =INDEX(traitement_nW_EOLES!$C:$C,MATCH($A5,traitement_nW_EOLES!$A:$A,0)) -> 0.12403561
A6: demand_H2_tot | B6: =INDEX(traitement_nW_EOLES!$C:$C,MATCH($A6,traitement_nW_EOLES!$A:$A,0)) -> 49.7645

Sheet Constants
A1: Parameter | B1: value | C1: unit
A2: year_simulated | B2: 2060
A3: social_cost_of_carbon | B3: 400 | C3: €/tCO2
A4: carbon_budget | B4: 0 | C4: MtCO2/y
A5: CO2_industry_demand | B5: 37245 | C5: GWh of CH4
A6: CO2_industry_prod | B6: 52087 | C6: GWh of CH4
A7: CO2_usable_industry | B7: 0.838
A8: fcr_requirement | B8: 0.562 | C8: GW
A9: h2_saltcavern_discharge_to_storage_ratio | B9: 0.00658
A10: h2_saltcavern_charge_to_storage_ratio | B10: 0.00168
A11: load_shift_maximum_power | B11: 1.89e-05 | C11: /hour
A12: load_shift_period | B12: 6 | C12: hour
A13: load_uncertainty | B13: 0.01
A14: load_variation | B14: 0.1
A15: ch4_reservoir_charge_to_discharge_ratio | B15: 0.5
A16: phs_charge_to_discharge_ratio | B16: 0.92
A17: tr_loss | B17: 0.0001
A18: biomethane_import | B18: 170 | C18: €/MWh
A19: min_CF_hourly_nuclear | B19: 0.2
A20: max_CF_hourly_nuclear | B20: 0.9
A21: annual_production_nuclear | B21: {=INDEX(Data_EOLES!$J$1:$EK$191,MATCH(A21,Data_EOLES!$C:$C,0),MATCH(year_simulated,VALUE(Data_EOLES!$J$1:$EK$1),0))} -> 12.85092 | C21: TWh
A22: capacity_factor_nuclear_yearly | B22: 0.7
A23: limit_biogas_extra_import | B23: 240 | C23: TWh

Sheet Costs
A1: tech | B1: capex | C1: fOM | D1: storage_capex | E1: construction_time | F1: discount_rate | G1: lifetime | H1: vOM
A2: offshore_float | B2: 5017.5 | C2: 100.3 | E2: 3.5 | F2: 0.04 | G2: 30 | H2: 0
A3: offshore_ground | B3: 4807 | C3: 79.9 | E3: 3.5 | F3: 0.04 | G3: 30 | H3: 0
A4: onshore | B4: 836.5 | C4: 32 | E4: 1.5 | F4: 0.04 | G4: 25 | H4: 0
A5: pv_ground | B5: 686.8 | C5: 15.3 | E5: 0.5 | F5: 0.04 | G5: 25 | H5: 0
A6: pv_roof_com | B6: 799.85 | C6: 17.85 | E6: 0.25 | F6: 0.04 | G6: 25 | H6: 0
A7: pv_roof_indiv | B7: 1538.5 | C7: 47.2 | E7: 0 | F7: 0.04 | G7: 25 | H7: 0
A8: river | B8: 1400 | C8: 74 | E8: 7 | F8: 0.04 | G8: 70 | H8: 0.000625
A9: marine | B9: 2375 | C9: 343.75 | E9: 0 | F9: 0.04 | G9: 25 | H9: 0
A10: waste | B10: 0 | C10: 0 | E10: 0 | F10: 0.04 | G10: 25 | H10: 0
A11: biomass_coge | B11: 3900 | C11: 78 | E11: 0 | F11: 0.04 | G11: 25 | H11: 0.004125
A12: geothermal_coge | B12: 7537.5 | C12: 150.75 | E12: 0 | F12: 0.04 | G12: 30 | H12: 0
A13: ocgt_coge | B13: 1212.5 | C13: 47.2875 | E13: 0 | F13: 0.04 | G13: 30 | H13: 0.005
... A19: lake | B19: 2500 | C19: 74 | E19: 7 | F19: 0.04 | G19: 70 | H19: 0
A20: phs | B20: 2500 | C20: 74 | D20: 85 | E20: 7 | F20: 0.04 | G20: 70 | H20: 0
A21: battery_1h | B21: 0 | C21: 14 | D21: 297 | E21: 0.25 | F21: 0.04 | G21: 20 | H21: 0
A22: battery_2h | B22: 0 | C22: 16 | D22: 244 | E22: 0.25 | F22: 0.04 | G22: 20 | H22: 0
A23: battery_4h | B23: 0 | C23: 24 | D23: 224 | E23: 0.25 | F23: 0.04 | G23: 20 | H23: 0
A24: battery_8h | B24: 0 | C24: 40 | D24: 210 | E24: 0.25 | F24: 0.04 | G24: 20 | H24: 0
A25: methanization | B25: 2875 | C25: 117.875 | E25: 2 | F25: 0.04 | G25: 20 | H25: 0.003875
A26: pyrogazification | B26: 3468.75 | C26: 312.1875 | E26: 2 | F26: 0.04 | G26: 20 | H26: 0.0444
A27: biogas_import | B27: 0 | C27: 0 | E27: 0 | F27: 0.04 | G27: 1 | H27: 0.175
A28: H2_import | B28: 0 | C28: 0 | E28: 0 | F28: 0.04 | G28: 1 | H28: 0.2
A29: natural_gas | B29: 0 | C29: 0 | E29: 0 | F29: 0.04 | G29: 1 | H29: 0
A30: electrolysis | B30: =500/0.67*1.15 -> 858.20896 | C30: 15 | E30: 2 | F30: 0.04 | G30: 20 | H30: 0
A31: methanation | B31: 1609.5 | C31: 97.125 | E31: 2 | F31: 0.04 | G31: 20 | H31: 0
A32: h2_saltcavern | B32: 0 | C32: 2.5 | D32: 0.35 | E32: 3 | F32: 0.04 | G32: 40 | H32: 0.00625
A33: ch4_reservoir | B33: 0 | C33: 0 | D33: 0 | E33: 0 | F33: 0.04 | G33: 30 | H33: 0.0025
A34: str_dummy | B34: 10000 | C34: 1250 | D34: 1000 | E34: 10 | F34: 0.04 | G34: 10 | H34: 1.25
A35: rsv_dummy | B35: 10000 | C35: 1250 | E35: 10 | F35: 0.04 | G35: 10 | H35: 1.25
A36: lost_load | B36: 0 | C36: 0 | E36: 0 | F36: 0.04 | G36: 1 | H36: 10

Sheet fuel_prices
A1: fuel | B1: fuel_prices_2020 | C1: fuel_prices_rate
A2: coal | B2: 0.0066 | C2: 0.0158
A3: natural_gas | B3: 0.0203 | C3: 0.0233

Sheet tech_parameters
A1: tech | B1: frr_requirements | C1: carbon_content | D1: carbon_footprint | E1: co2_fraction | F1: co2_usable | G1: conversion_efficiency | H1: efficiency_storage_in | I1: efficiency_storage_out | J1: ramp_rate | K1: capacity_factor
A2: offshore_float | B2: 0.032 | D2: 0.007 | K2: 0.39
A3: offshore_ground | B3: 0.032 | D3: 0.007 | K3: 0.37
A4: onshore | B4: 0.032 | D4: 0.013 | K4: 0.29
A5: pv_ground | B5: 0.014 | D5: 0.014 | K5: 0.14
A6: pv_roof_com | B6: 0.014 | D6: 0.014 | K6: 0.12
A7: pv_roof_indiv | B7: 0.014 | D7: 0.014 | K7: 0.13
A8: river | B8: 0 | D8: 0.006 | K8: 0.3
A9: marine | B9: 0 | D9: 0 | K9: 0.45
A10: waste | B10: 0 | D10: 0 | K10: 0.173
A11: biomass_coge | B11: 0 | D11: 0 | K11: 0.4
A12: geothermal_coge | B12: 0 | D12: 0 | K12: 0.799
A13: ocgt_coge | B13: 0 | D13: 0.098 | G13: 0.4 | K13: 0.13
A14: nuclear | D14: 0.006 | J14: 0.5 | K14: 0.7
A15: coal | C15: 0.855 | D15: 1.1 | J15: 1.84
A16: ch4_ocgt | D16: 0.081 | G16: 0.4 | J16: 8.18
A17: ch4_ccgt | D17: 0.12 | G17: 0.6 | J17: 3.44
A18: h2_ccgt | D18: 0.035 | G18: 0.6 | J18: 3.44
A19: lake | D19: 0.006 | I19: 0.85
A20: phs | D20: 0.006 | H20: 0.9 | I20: 0.85
A21: battery_1h | D21: 0.058 | H21: 1 | I21: 0.9
A22: battery_2h | D22: 0.058 | H22: 1 | I22: 0.9
A23: battery_4h | D23: 0.058 | H23: 1 | I23: 0.9
A24: battery_8h | D24: 0.058 | H24: 1 | I24: 0.9
A25: methanization | E25: 0.42 | F25: 0.514
A26: pyrogazification | E26: 0.34 | F26: 0.676
A27: biogas_import
A28: H2_import
A29: natural_gas | C29: 0.2136 | D29: 0.2136
A30: electrolysis | D30: 0.005 | G30: {=INDEX(Data_EOLES!$J$1:$EK$191,MATCH(G$1&"_"&$A30,Data_EOLES!$C:$C,0),MATCH(year_simulated,VALUE(Data_EOLES!$J$1:$EK$1),0))} -> 0.67827
A31: methanation | G31: {=INDEX(Data_EOLES!$J$1:$EK$191,MATCH(G$1&"_"&$A31,Data_EOLES!$C:$C,0),MATCH(year_simulated,VALUE(Data_EOLES!$J$1:$EK$1),0))*G30} -> 0.56183139
A32: h2_saltcavern | D32: 0 | H32: 1 | I32: 1
A33: ch4_reservoir | D33: 0 | H33: 1 | I33: 1
A34: str_dummy | D34: 0 | H34: 1 | I34: 1
A35: rsv_dummy | D35: 0
A36: lost_load | D36: 0

Sheet reserve
A1: reserve | B1: reserve_activation_rate | C1: reserve_activation_time
A2: fcr | B2: 0.078 | C2: 0.00833
A3: frr | B3: 0.182 | C3: 0.0833

Sheet exist_cap
A1: tech | B1: FR | C1: ES | D1: IT | E1: CH | F1: DE | G1: BE | H1: UK | I1: NL | J1: IE | K1: PT
A2: offshore_float
A3: offshore_ground
A4: onshore
A5: pv_ground
A6: pv_roof_com
A7: pv_roof_indiv
A8: river | B8: {=INDEX(Data_EOLES!$J$1:$EK$191,MATCH("max_cap"&"_"&$A8,Data_EOLES!$C:$C,0),MATCH(year_simulated,VALUE(Data_EOLES!$J$1:$EK$1),0))} -> 7.6 | C8: =4.5 -> 4.5 | D8: =13 -> 13 | E8: =8.2 -> 8.2 | F8: =3.9 -> 3.9 | G8: =0.1 -> 0.1 | H8: =2.2 -> 2.2 | I8: =0.04 -> 0.04 | J8: =0.2 -> 0.2 | K8: =0.8 -> 0.8
A9: marine | B9: 0.25 | C9: =3.7 -> 3.7 | D9: =0 -> 0 | E9: =0 -> 0 | F9: =0 -> 0 | G9: =0 -> 0 | H9: =0 -> 0 | I9: =0 -> 0 | J9: =0 -> 0 | K9: =0 -> 0
A10: waste
A11: biomass_coge
A12: geothermal_coge
A13: ocgt_coge
A14: nuclear | B14: {=INDEX(Data_EOLES!$J$1:$EK$191,MATCH("annual_production"&"_"&$A14,Data_EOLES!$C:$C,0),MATCH(year_simulated,VALUE(Data_EOLES!$J$1:$EK$1),0))/INDEX(tech_parameters!$A$1:$CA$301, MATCH($A14,tech_parameters!$A$1:$A$301,0), MATCH("capacity_factor",tech_parameters!$A$1:$CA$1,0))/8.76} -> 2.0957143 | C14: 0 | D14: 0 | E14: 0 | F14: 0 | G14: 0 | H14: 0 | I14: 0 | J14: 0 | K14: 0
A15: coal
A16: ch4_ocgt
A17: ch4_ccgt
A18: h2_ccgt
A19: lake | B19: {=INDEX(Data_EOLES!$J$1:$EK$191,MATCH("max_cap"&"_"&$A19,Data_EOLES!$C:$C,0),MATCH(year_simulated,VALUE(Data_EOLES!$J$1:$EK$1),0))} -> 13.03119 | C19: =11.7 -> 11.7 | D19: =9 -> 9 | E19: =7.9 -> 7.9 | F19: =0.4 -> 0.4 | G19: =0 -> 0 | H19: =0 -> 0 | I19: =0 -> 0 | J19: =0 -> 0 | K19: =2.8 -> 2.8
A20: phs | B20: 5.06 | C20: 6.4 | D20: 7.22 | E20: 3.12 | F20: 6.5 | G20: 1.3 | H20: 2.8 | I20: 0 | J20: 0 | K20: 4.7
A21: battery_1h
A22: battery_2h
A23: battery_4h
A24: battery_8h
A25: methanization
A26: pyrogazification
A27: biogas_import
A28: H2_import
A29: natural_gas
A30: electrolysis
A31: methanation
A32: h2_saltcavern
... A36: lost_load

Sheet exist_en_cap
A1: tech | B1: FR | C1: ES | D1: IT | E1: CH | F1: DE | G1: BE | H1: UK | I1: NL | J1: IE | K1: PT
A2: offshore_float
A3: offshore_ground
A4: onshore
A5: pv_ground
A6: pv_roof_com
A7: pv_roof_indiv
A8: river
A9: marine
A10: waste
A11: biomass_coge
A12: geothermal_coge
A13: ocgt_coge
... A18: h2_ccgt
